========== test_q3c.TestImageSampler.test_01_shape (Check if output is numpy array of correct shape): FAIL ==========

## Feedback: Traceback (most recent call last):
  File "/data/markus/workspace/workers/autotsw3/test_q3c.py", line 45, in test_01_shape
    output = nb.image_sampler(self.theta, self.pi, self.num_images)
NameError: name 'sampled_images' is not defined

During handling of the above exception, another exception occurred:

Traceback (most recent call last):
  File "/data/markus/workspace/workers/autotsw3/test_q3c.py", line 49, in test_01_shape
    self.fail(msg)
AssertionError: 
When we called naive_bayes.image_sampler([[0.225458   0.84464856 0.52106402 ... 0.03666616 0.31866816 0.5579401 ]
 [0.92947924 0.78042123 0.60981974 ... 0.9899247  0.45980785 0.71688643]
 [0.63137543 0.2166453  0.13909153 ... 0.68994204 0.95615142 0.95808783]
 ...
 [0.36627969 0.9241409  0.51399773 ... 0.60225751 0.42340761 0.46618977]
 [0.60558226 0.2707544  0.27310216 ... 0.73777427 0.60851525 0.38711639]
 [0.80370855 0.42146678 0.27155025 ... 0.48495963 0.52307837 0.92643607]], [0.1 0.1 0.1 0.1 0.1 0.1 0.1 0.1 0.1 0.1], 5).shape,
your code failed:
Traceback (most recent call last):
  File "/data/markus/workspace/workers/autotsw3/test_q3c.py", line 45, in test_01_shape
    output = nb.image_sampler(self.theta, self.pi, self.num_images)
  File "/data/markus/workspace/workers/autotsw3/naive_bayes.py", line 235, in image_sampler
    return sampled_images
NameError: name 'sampled_images' is not defined




========== test_q3c.TestImageSampler.test_02_random_functions (Test to check if `np.random.choice` and `np.random.binomial` are called ): FAIL ==========

## Feedback: Traceback (most recent call last):
  File "/data/markus/workspace/workers/autotsw3/test_q3c.py", line 64, in test_02_random_functions
    _ = nb.image_sampler(self.theta, self.pi, self.num_images)
  File "/data/markus/workspace/workers/autotsw3/naive_bayes.py", line 235, in image_sampler
    return sampled_images
NameError: name 'sampled_images' is not defined

During handling of the above exception, another exception occurred:

Traceback (most recent call last):
  File "/local/packages/python-3.8/lib/python3.8/unittest/mock.py", line 1325, in patched
    return func(*newargs, **newkeywargs)
  File "/data/markus/workspace/workers/autotsw3/test_q3c.py", line 67, in test_02_random_functions
    self.fail(msg)
AssertionError: 
When we called naive_bayes.image_sampler([[0.18119905 0.03523915 0.36404826 ... 0.63411503 0.28084312 0.9202908 ]
 [0.98349639 0.84750865 0.54042463 ... 0.97063204 0.95978843 0.78953121]
 [0.15520997 0.14043941 0.24015148 ... 0.80442002 0.30428715 0.14351427]
 ...
 [0.82287448 0.1246187  0.36484678 ... 0.87315279 0.25864313 0.06739594]
 [0.2057566  0.10172631 0.03808028 ... 0.54439681 0.49779104 0.23053146]
 [0.06653889 0.25780146 0.43213065 ... 0.48942827 0.20669109 0.71203719]], [0.1 0.1 0.1 0.1 0.1 0.1 0.1 0.1 0.1 0.1], 5),
your code failed:
Traceback (most recent call last):
  File "/data/markus/workspace/workers/autotsw3/test_q3c.py", line 64, in test_02_random_functions
    _ = nb.image_sampler(self.theta, self.pi, self.num_images)
  File "/data/markus/workspace/workers/autotsw3/naive_bayes.py", line 235, in image_sampler
    return sampled_images
NameError: name 'sampled_images' is not defined




